<?xml version="1.0" ?>
<robot name="plate">
    <link name="base_link">
        <inertial>
            <origin xyz="0 0 0.0" rpy="0 -0 0" />
            <mass value="1" />
            <inertia ixx="0.1" iyy="0.1" izz="0.1" ixy="0" ixz="0" iyz="0" />
        </inertial>
    </link>
    <link name="link0">
        <inertial>
            <origin xyz="0 0 0.14" rpy="0 -0 0" />
            <mass value="4" />
            <inertia ixx="0.4" iyy="0.4" izz="0.4" ixy="0" ixz="0" iyz="0" />
        </inertial>

    </link>
    <link name="link1">
        <inertial>
            <origin xyz="0 0 0.0" rpy="0 -0 0" />
            <mass value="1" />
            <inertia ixx="0.1" iyy="0.1" izz="0.1" ixy="0" ixz="0" iyz="0" />
        </inertial>
        <visual>
            <origin xyz="0 0 0" rpy="0 -0 0" />
            <geometry>
                <box size="0.25 0.25 0.025"/>
            </geometry>
            <material name="material_plate">
                <color rgba="0.2 0.9 0.8 1.0" />
            </material>
        </visual>
        <collision>
            <origin xyz="0 0 0" rpy="0 -0 0" />
            <geometry>
                <box size="0.25 0.25 0.025"/>
            </geometry>
        </collision>
    </link>

    <joint name="j0" type="revolute">
        <parent link="base_link" />
        <child link="link0" />
        <origin xyz="0.000000 0.000000 0.0" rpy="0.000000 0.000000 0.000000" />
        <axis xyz="1 0 0" />
        <limit lower="-2.967" upper="2.967" effort="176" velocity="1.7104" />
    </joint>
    <joint name="j1" type="revolute">
        <parent link="link0" />
        <child link="link1" />
        <origin xyz="0.000000 0.000000 0.0" rpy="0.000000 0.000000 0.000000" />
        <axis xyz="0 1 0" />
        <limit lower="-2.0944" upper="2.0944" effort="176" velocity="1.7104" />
    </joint>
</robot>
